<?xml version="1.0"?>
<!-- =================================================================================== -->
<!-- |    This document was autogenerated by xacro from
/home/blazej/ros/arm_ws/src/kalman_arm/arm_description/urdf/robot.xacro | -->
<!-- |    EDITING THIS FILE BY HAND IS NOT RECOMMENDED                                 | -->
<!-- =================================================================================== -->
<robot name="arm">
    <link name="world" />
    <link name="flange" />
    <joint name="fix_flange" type="fixed">
        <parent link="world" />
        <child link="flange" />
    </joint>
    <link name="arm_link">
        <visual>
            <geometry>
                <cylinder length="0" radius="0.089" />
            </geometry>
            <origin rpy="0 0 0" xyz="0 0 0" />
        </visual>
        <collision>
            <geometry>
                <cylinder length="0" radius="0.089" />
            </geometry>
            <origin rpy="0 0 0" xyz="0 0 0" />
        </collision>

        <inertial>
            <mass value="0.1" />
            <inertia ixx="0.03" iyy="0.03" izz="0.03" ixy="0.0" ixz="0.0" iyz="0.0" />
        </inertial>

    </link>
    <link name="link1">
        <visual>
            <geometry>
                <box size="0.1275 0.089 0.089" />
            </geometry>
            <origin rpy="0 0 0" xyz="0.06375 0 0" />

        </visual>
        <collision>
            <geometry>
                <box size="0.1275 0.089 0.089" />
            </geometry>
            <origin rpy="0 0 0" xyz="0.06375 0 0" />
        </collision>

        <inertial>
            <mass value="0.1" />
            <inertia ixx="0.03" iyy="0.03" izz="0.03" ixy="0.0" ixz="0.0" iyz="0.0" />
        </inertial>

    </link>
    <joint name="joint_1" type="revolute">
        <axis xyz="0 0 1" />
        <limit effort="1000.0" lower="-3.1415926" upper="3.1415926" velocity="0.5" />
        <parent link="arm_link" />
        <child link="link1" />
        <origin rpy="0 0 1.570796" xyz="0 0 0.142" />
    </joint>
    <link name="link2">
        <visual>
            <geometry>
                <cylinder length="0.73" radius="0.0125" />
            </geometry>
            <!--      0.07+0.05 / 2-->
            <origin rpy="0 0 0" xyz="0.14 0 0.365" />

        </visual>
        <collision>
            <geometry>
                <cylinder length="0.73" radius="0.0125" />
            </geometry>
            <origin rpy="0 0 0" xyz="0.14 0 0.365" />
        </collision>

        <inertial>
            <mass value="0.1" />
            <inertia ixx="0.03" iyy="0.03" izz="0.03" ixy="0.0" ixz="0.0" iyz="0.0" />
        </inertial>

    </link>
    <joint name="joint_2" type="revolute">
        <axis xyz="1 0 0" />
        <limit effort="1000.0" lower="-3.1415926" upper="3.1415926" velocity="0.5" />
        <parent link="link1" />
        <child link="link2" />
        <origin xyz="0 0 0" />
    </joint>
    <link name="link3">
        <visual>
            <geometry>
                <box size="0.115 0.089 0.089" />
            </geometry>
            <origin rpy="0 0 0" xyz="0.07 0 0" />

        </visual>
        <collision>
            <geometry>
                <box size="0.115 0.089 0.089" />
            </geometry>
            <origin rpy="0 0 0" xyz="0.07 0 0" />
        </collision>

        <inertial>
            <mass value="0.1" />
            <inertia ixx="0.03" iyy="0.03" izz="0.03" ixy="0.0" ixz="0.0" iyz="0.0" />
        </inertial>

    </link>
    <joint name="joint_3" type="revolute">
        <axis xyz="1 0 0" />
        <limit effort="1000.0" lower="-3.1415926" upper="3.1415926" velocity="0.5" />
        <parent link="link2" />
        <child link="link3" />
        <origin xyz="0 0 0.73" />
    </joint>
    <link name="link4">
        <visual>
            <geometry>
                <cylinder length="0.53" radius="0.0125" />
            </geometry>
            <origin rpy="0 0 0" xyz="0 0 0.265" />

        </visual>
        <collision>
            <geometry>
                <cylinder length="0.53" radius="0.0125" />
            </geometry>
            <origin rpy="0 0 0" xyz="0 0 0.265" />
        </collision>

        <inertial>
            <mass value="0.1" />
            <inertia ixx="0.03" iyy="0.03" izz="0.03" ixy="0.0" ixz="0.0" iyz="0.0" />
        </inertial>

    </link>
    <joint name="joint_4" type="revolute">
        <axis xyz="0 0 1" />
        <limit effort="1000.0" lower="-3.14" upper="3.14" velocity="0.5" />
        <parent link="link3" />
        <child link="link4" />
        <!--        <origin xyz="0 0 0.54"/>-->
    </joint>
    <link name="link5">
        <visual>
            <geometry>
                <cylinder length="0.001" radius="0.0001" />
            </geometry>
            <origin rpy="0 0 0" xyz="0 0 0.03" />

        </visual>
        <collision>
            <geometry>
                <cylinder length="0.089" radius="0.02" />
            </geometry>
            <origin rpy="0 0 0" xyz="0 0 0.03" />
        </collision>

        <inertial>
            <mass value="0.1" />
            <inertia ixx="0.03" iyy="0.03" izz="0.03" ixy="0.0" ixz="0.0" iyz="0.0" />
        </inertial>

    </link>
    <joint name="joint_5" type="revolute">
        <axis xyz="0 0 1" />
        <limit effort="1000.0" lower="-3.14" upper="3.14" velocity="0.5" />
        <parent link="link4" />
        <child link="link5" />
        <origin rpy="0 1.5707960796 0" xyz="-0.06375 0 0.53" />
    </joint>
    <link name="link5_ext">
        <visual>
            <geometry>
                <cylinder length="0.089" radius="0.02" />
            </geometry>
            <origin rpy="0 0 0" xyz="0 0 0.03" />

        </visual>
        <collision>
            <geometry>
                <cylinder length="0.089" radius="0.02" />
            </geometry>
            <origin rpy="0 0 0" xyz="0 0 0.03" />
        </collision>

        <inertial>
            <mass value="0.1" />
            <inertia ixx="0.03" iyy="0.03" izz="0.03" ixy="0.0" ixz="0.0" iyz="0.0" />
        </inertial>

    </link>
    <link name="link6">
        <visual>
            <geometry>
                <cylinder length="0.03" radius="0.0445" />
            </geometry>
            <origin rpy="0 0 0" xyz="0 0 -0.005" />

        </visual>
        <collision>
            <geometry>
                <cylinder length="0.03" radius="0.0445" />
            </geometry>
            <origin rpy="0 0 0" xyz="0 0 -0.005" />
        </collision>

        <inertial>
            <mass value="0.1" />
            <inertia ixx="0.03" iyy="0.03" izz="0.03" ixy="0.0" ixz="0.0" iyz="0.0" />
        </inertial>

    </link>

    <link name="link6_ext">
        <inertial>
            <mass value="0.1" />
            <inertia ixx="0.03" iyy="0.03" izz="0.03" ixy="0.0" ixz="0.0" iyz="0.0" />
        </inertial>
    </link>
    <joint name="joint_5_fix" type="fixed">
        <parent link="link5" />
        <child link="link5_ext" />
        <origin rpy="0 -1.57 0" xyz="0 0 0.065" />
    </joint>
    <joint name="joint_6_fix" type="fixed">
        <parent link="link6" />
        <child link="link6_ext" />
        <origin rpy="-1.57 -1.57 0" xyz="0 0 0" />

    </joint>

    <joint name="joint_6" type="revolute">
        <axis xyz="0 0 1" />
        <limit effort="1000.0" lower="-1.57" upper="1.57" velocity="0.5" />
        <parent link="link5_ext" />
        <child link="link6" />
        <origin rpy="0 0 0" xyz="0 0 0.089" />
    </joint>

    <link name="gripper_fixed">
        <visual>
            <geometry>
                <box size="0.12 0.05 0.05" />
            </geometry>

            <origin rpy="0 0 0" xyz="0.065 0 0" />
        </visual>
        <collision>
            <geometry>
                <box size="0.12 0.05 0.05" />
            </geometry>
            <origin rpy="0 0 0" xyz="0.065 0 0" />

        </collision>
        <inertial>
            <mass value="0.1" />
            <inertia ixx="0.03" iyy="0.03" izz="0.03" ixy="0.0" ixz="0.0" iyz="0.0" />
        </inertial>
    </link>

    <joint name="gripper_fixed_joint" type="fixed">
        <parent link="link6_ext" />
        <child link="gripper_fixed" />
        <origin rpy="0 0 0" xyz="0 -0.04 0" />

    </joint>

    <link name="gripper_moving">
        <visual>
            <geometry>
                <box size="0.12 0.05 0.05" />
            </geometry>

            <origin rpy="0 0 0" xyz="0.065 0 0" />

        </visual>
        <collision>
            <geometry>
                <box size="0.12 0.05 0.05" />
            </geometry>
            <origin rpy="0 0 0" xyz="0.065 0 0" />

        </collision>
        <inertial>
            <mass value="0.1" />
            <inertia ixx="0.03" iyy="0.03" izz="0.03" ixy="0.0" ixz="0.0" iyz="0.0" />
        </inertial>
    </link>

    <joint name="gripper_moving_joint" type="revolute">
        <parent link="link6_ext" />
        <child link="gripper_moving" />
        <axis xyz="0 0 1" />
        <limit effort="1000.0" lower="-0.1" upper="1.57" velocity="0.5" />
        <origin rpy="0 0 0" xyz="0 0.04 0" />
    </joint>


    <joint name="fix" type="fixed">
        <parent link="flange" />
        <child link="arm_link" />
        <origin rpy="0 0 0" />
    </joint>

    <transmission name="trans_joint_1">
        <type>transmission_interface/SimpleTransmission</type>
        <joint name="joint_1">
            <hardwareInterface>hardware_interface/PositionJointInterface</hardwareInterface>
        </joint>
        <actuator name="joint_1_motor">
            <hardwareInterface>hardware_interface/PositionJointInterface</hardwareInterface>
            <mechanicalReduction>1</mechanicalReduction>
        </actuator>
    </transmission>
    <transmission name="trans_joint_2">
        <type>transmission_interface/SimpleTransmission</type>
        <joint name="joint_2">
            <hardwareInterface>hardware_interface/PositionJointInterface</hardwareInterface>
        </joint>
        <actuator name="joint_2_motor">
            <hardwareInterface>hardware_interface/PositionJointInterface</hardwareInterface>
            <mechanicalReduction>1</mechanicalReduction>
        </actuator>
    </transmission>
    <transmission name="trans_joint_3">
        <type>transmission_interface/SimpleTransmission</type>
        <joint name="joint_3">
            <hardwareInterface>hardware_interface/PositionJointInterface</hardwareInterface>
        </joint>
        <actuator name="joint_3_motor">
            <hardwareInterface>hardware_interface/PositionJointInterface</hardwareInterface>
            <mechanicalReduction>1</mechanicalReduction>
        </actuator>
    </transmission>
    <transmission name="trans_joint_4">
        <type>transmission_interface/SimpleTransmission</type>
        <joint name="joint_4">
            <hardwareInterface>hardware_interface/PositionJointInterface</hardwareInterface>
        </joint>
        <actuator name="joint_4_motor">
            <hardwareInterface>hardware_interface/PositionJointInterface</hardwareInterface>
            <mechanicalReduction>1</mechanicalReduction>
        </actuator>
    </transmission>
    <transmission name="trans_joint_5">
        <type>transmission_interface/SimpleTransmission</type>
        <joint name="joint_5">
            <hardwareInterface>hardware_interface/PositionJointInterface</hardwareInterface>
        </joint>
        <actuator name="joint_5_motor">
            <hardwareInterface>hardware_interface/PositionJointInterface</hardwareInterface>
            <mechanicalReduction>1</mechanicalReduction>
        </actuator>
    </transmission>
    <transmission name="trans_joint_6">
        <type>transmission_interface/SimpleTransmission</type>
        <joint name="joint_6">
            <hardwareInterface>hardware_interface/PositionJointInterface</hardwareInterface>
        </joint>
        <actuator name="joint_6_motor">
            <hardwareInterface>hardware_interface/PositionJointInterface</hardwareInterface>
            <mechanicalReduction>1</mechanicalReduction>
        </actuator>
    </transmission>

    <transmission name="trans_gripper">
        <type>transmission_interface/SimpleTransmission</type>
        <joint name="gripper_moving_joint">
            <hardwareInterface>hardware_interface/PositionJointInterface</hardwareInterface>
        </joint>
        <actuator name="gripper_motor">
            <hardwareInterface>hardware_interface/PositionJointInterface</hardwareInterface>
            <mechanicalReduction>1</mechanicalReduction>
        </actuator>
    </transmission>
    <gazebo>
        <plugin name="gazebo_ros_control" filename="libgazebo_ros_control.so">
            <robotNamespace>/</robotNamespace>
        </plugin>
    </gazebo>

</robot>